Workbook

Sheet 49
C3: Programa Conservação e Manutenção da Malha Viária da Cidade de São Paulo - SMSUB
C5: Sub | D5: Denominação da Via | E5: Nº Processo de Medição | F5: N° Doc SEI | G5: Janeiro | H5: Fevereiro | I5: Março | J5: Abril | K5: Maio | L5: Junho | M5: Julho | N5: Agosto | O5: Setembro | P5: Outubro | Q5: Novembro | R5: Dezembro | S5: Área Total de Capa Executada (m²)
C7: Área Recapeada em 2025
C9: AD | D9: Rua Salvador Dali – Trecho II | E9: 6012.2024/0028507-0 | F9: 115343424 | G9: 4907.42 | S9: 4907.42
C10: AD | D10: Rua Gonçalo Camacho | E10: 6012.2024/0031004-0 | F10: 116990791 | G10: 4420.03 | S10: 4420.03
C11: AF | D11: Rua Templários | E11: 6012.2024/0030690-6 | F11: 116564362 | G11: 9685.98 | S11: 9685.98
C12: BT | D12: Rua Boturoca | E12: 6012.2024/0031017-2 | F12: 117003012 | G12: 3717.06 | S12: 3717.06
C13: BT | D13: Rua Célio Manuel Vieira | E13: 6012.2024/0031017-2 | F13: 117003012 | G13: 1037.52 | S13: 1037.52
C14: BT | D14: Rua Conde Luiz Eduardo Matarazzo (Inclui Rua José Franco Silva) | E14: 6012.2024/0031017-2 | F14: 117003012 | G14: 11810.71 | S14: 11810.71
C15: BT | D15: Rua Corinto | E15: 6012.2024/0031017-2 | F15: 117003012 | G15: 4411.4 | S15: 4411.4
C16: BT | D16: Rua Dr. Italo Eboli | E16: 6012.2024/0031017-2 | F16: 117003012 | G16: 1703.55 | S16: 1703.55
C17: BT | D17: Rua Eng. Wily Fischer | E17: 6012.2024/0031017-2 | F17: 117003012 | G17: 4599.38 | S17: 4599.38
C18: BT | D18: Rua Eusébio de Paula Marcondes | E18: 6012.2024/0031017-2 | F18: 117003012 | G18: 11520.8 | S18: 11520.8
C19: BT | D19: Rua Frei Inácio da Conceição | E19: 6012.2024/0031017-2 | F19: 117003012 | G19: 4415.56 | S19: 4415.56
C20: BT | D20: Rua Hans Staden | E20: 6012.2024/0031017-2 | F20: 117003012 | G20: 1711.21 | S20: 1711.21
... C196: VP | D196: Rua São Cirilo | E196: 6012.2025/0001753-1 | F196: 119004423 | G196: 3683.34 | S196: 3683.34
C197: AF | D197: Rua Grecco | E197: 6012.2025/0003805-9 | F197: 120918356 | H197: 8182.92 | S197: 8182.92
C198: AF | D198: Rua Vacanga | E198: 6012.2025/0003805-9 | F198: 120918356 | H198: 5534.81 | S198: 5534.81
C199: BT | D199: Rua Iquiririm | E199: 6012.2025/0003609-9 | F199: 120756164 | H199: 12635.36 | S199: 12635.36
C200: CL | D200: Rua Chapada Velha | E200: 6012.2025/0003609-9 | F200: 120756164 | H200: 4342.61 | S200: 4342.61
C201: CL | D201: Rua Francisco Pessoa | E201: 6012.2025/0003609-9 | F201: 120756164 | H201: 10050.93 | S201: 10050.93
C202: CL | D202: Rua Padre Joaquim Correia de Almeida | E202: 6012.2025/0003609-9 | F202: 120756164 | H202: 2702.7 | S202: 2702.7
C203: CL | D203: Rua Sofia Ambuda | E203: 6012.2025/0003609-9 | F203: 120756164 | H203: 1090.38 | S203: 1090.38
C204: CT | D204: Rua Humberto Teixeira | E204: 6012.2025/0003797-4 | F204: 120915101 | H204: 1160 | S204: 1160
C205: CT | D205: Rua Santo Rizzo | E205: 6012.2025/0003797-4 | F205: 120915101 | H205: 2395.87 | S205: 2395.87
C206: CT | D206: Rua Sen. Nelson Carneiro | E206: 6012.2025/0003797-4 | F206: 120915101 | H206: 7188.27 | S206: 7188.27
C207: EM | D207: Rua Antonio Carlos Lamego | E207: 6012.2025/0003472-0 | F207: 120702690 | H207: 4133.69 | S207: 4133.69
C208: EM | D208: Rua Antonio Tertuliano | E208: 6012.2025/0003472-0 | F208: 120702690 | H208: 7462.1 | S208: 7462.1
... C277: VP | D277: Rua Monteiro Soares Filho | E277: 6012.2025/0003805-9 | F277: 120918356 | H277: 7090.64 | S277: 7090.64
C278: AF | D278: Rua Ricardo Gumblenton Daunt | E278: 6012.2025/0005413-5 | F278: 122687263 | I278: 5266.09 | S278: 5266.09
C279: CT | D279: Rua Apostolo Simao Pedro | E279: 6012.2025/0005372-4 | F279: 122640370 | I279: 5525.02 | S279: 5525.02
C280: CT | D280: Rua Igarape Agua Azul (Inclui Trecho da Rua Nascer do Sol) | E280: 6012.2025/0005372-4 | F280: 122640370 | I280: 10860.45 | S280: 10860.45
C281: CT | D281: Rua Luiz josé Costa Leandro | E281: 6012.2025/0005372-4 | F281: 122640370 | I281: 4517.13 | S281: 4517.13
C282: CT | D282: Rua Olimpia Montani | E282: 6012.2025/0005372-4 | F282: 122640370 | I282: 2404.27 | S282: 2404.27
C283: CT | D283: Rua Varzea Nova | E283: 6012.2025/0005372-4 | F283: 122640370 | I283: 6317.75 | S283: 6317.75
C284: CT | D284: Rua Rei Davi | E284: 6012.2025/0005372-4 | F284: 122640370 | I284: 5278.4 | S284: 5278.4
C285: EM | D285: Rua Pinheiro de Ulhoa Cintra | E285: 6012.2025/0005416-0 | F285: 122690563 | I285: 9628.69 | S285: 9628.69
C286: EM | D286: Rua Prof. Ernestina Loureiro de Miranda | E286: 6012.2025/0005416-0 | F286: 122690563 | I286: 6729.56 | S286: 6729.56
C287: EM | D287: Rua Raimundo Machado | E287: 6012.2025/0005416-0 | F287: 122690563 | I287: 5176.45 | S287: 5176.45
C288: G | D288: Rua Guiticoróia | E288: 6012.2025/0005372-4 | F288: 122640370 | I288: 1772.3 | S288: 1772.3
...

Sheet Área Por Subprefeitura
B2: Região | C2: Subprefeitura | D2: Subprefeitura (Por Extenso) | E2: Área Executada (m²)
E3: 45658 | F3: 45689 | G3: 45717 | H3: 45748 | I3: 45778 | J3: 45809 | K3: 45839 | L3: 45870 | M3: 45901 | N3: 45931 | O3: 45962 | P3: 45992 | Q3: 46023 | R3: 46054 | S3: 46082 | T3: 46113 | U3: 46143 | V3: 46174 | W3: 46204 | X3: 46235 | Y3: 46266 | Z3: 46296 | AA3: 46327 | AB3: 46357 | AC3: Total 2025
B4: Sul | C4: AD | D4: Cidade Ademar | E4: =SUMIFS('49'!G$9:G$567,'49'!$C$9:$C$567,$C4) -> 15994.67 | F4: =SUMIFS('49'!H$9:H$567,'49'!$C$9:$C$567,$C4) -> 0 | G4: =SUMIFS('49'!I$9:I$567,'49'!$C$9:$C$567,$C4) -> 0 | H4: =SUMIFS('49'!J$9:J$567,'49'!$C$9:$C$567,$C4) -> 0 | I4: =SUMIFS('49'!K$9:K$567,'49'!$C$9:$C$567,$C4) -> 0 | J4: =SUMIFS('49'!L$9:L$567,'49'!$C$9:$C$567,$C4) -> 0 | K4: =SUMIFS('49'!M$9:M$567,'49'!$C$9:$C$567,$C4) -> 0 | L4: =SUMIFS('49'!N$9:N$567,'49'!$C$9:$C$567,$C4) -> 0 | ... P4: =SUMIFS('49'!R$9:R$567,'49'!$C$9:$C$567,$C4) -> 0 | Q4: =SUMIFS('49'!G$575:G$594,'49'!$C$575:$C$594,$C4) -> 0 | R4: =SUMIFS('49'!H$575:H$594,'49'!$C$575:$C$594,$C4) -> 0 | S4: =SUMIFS('49'!I$575:I$594,'49'!$C$575:$C$594,$C4) -> 0 | T4: =SUMIFS('49'!J$575:J$594,'49'!$C$575:$C$594,$C4) -> 0 | U4: =SUMIFS('49'!K$575:K$594,'49'!$C$575:$C$594,$C4) -> 0 | V4: =SUMIFS('49'!L$575:L$594,'49'!$C$575:$C$594,$C4) -> 0 | W4: =SUMIFS('49'!M$575:M$594,'49'!$C$575:$C$594,$C4) -> 0 | X4: =SUMIFS('49'!N$575:N$594,'49'!$C$575:$C$594,$C4) -> 0 | ... AB4: =SUMIFS('49'!R$575:R$594,'49'!$C$575:$C$594,$C4) -> 0 | AC4: =SUM(E4:AB4) -> 15994.67
B5: Leste | C5: AF | D5: Aricanduva - Vila Formosa - Carrão | E5: =SUMIFS('49'!G$9:G$567,'49'!$C$9:$C$567,$C5) -> 59451.41 | F5: =SUMIFS('49'!H$9:H$567,'49'!$C$9:$C$567,$C5) -> 13717.73 | G5: =SUMIFS('49'!I$9:I$567,'49'!$C$9:$C$567,$C5) -> 5266.09 | H5: =SUMIFS('49'!J$9:J$567,'49'!$C$9:$C$567,$C5) -> 56694.9 | I5: =SUMIFS('49'!K$9:K$567,'49'!$C$9:$C$567,$C5) -> 0 | J5: =SUMIFS('49'!L$9:L$567,'49'!$C$9:$C$567,$C5) -> 0 | K5: =SUMIFS('49'!M$9:M$567,'49'!$C$9:$C$567,$C5) -> 9546.59 | L5: =SUMIFS('49'!N$9:N$567,'49'!$C$9:$C$567,$C5) -> 0 | ... P5: =SUMIFS('49'!R$9:R$567,'49'!$C$9:$C$567,$C5) -> 0 | Q5: =SUMIFS('49'!G$575:G$594,'49'!$C$575:$C$594,$C5) -> 0 | R5: =SUMIFS('49'!H$575:H$594,'49'!$C$575:$C$594,$C5) -> 0 | S5: =SUMIFS('49'!I$575:I$594,'49'!$C$575:$C$594,$C5) -> 0 | T5: =SUMIFS('49'!J$575:J$594,'49'!$C$575:$C$594,$C5) -> 0 | U5: =SUMIFS('49'!K$575:K$594,'49'!$C$575:$C$594,$C5) -> 0 | V5: =SUMIFS('49'!L$575:L$594,'49'!$C$575:$C$594,$C5) -> 0 | W5: =SUMIFS('49'!M$575:M$594,'49'!$C$575:$C$594,$C5) -> 0 | X5: =SUMIFS('49'!N$575:N$594,'49'!$C$575:$C$594,$C5) -> 0 | ... AB5: =SUMIFS('49'!R$575:R$594,'49'!$C$575:$C$594,$C5) -> 0 | AC5: =SUM(E5:AB5) -> 165019.83
B6: Oeste | C6: BT | D6: Butantã | E6: =SUMIFS('49'!G$9:G$567,'49'!$C$9:$C$567,$C6) -> 85761.61 | F6: =SUMIFS('49'!H$9:H$567,'49'!$C$9:$C$567,$C6) -> 12635.36 | G6: =SUMIFS('49'!I$9:I$567,'49'!$C$9:$C$567,$C6) -> 0 | H6: =SUMIFS('49'!J$9:J$567,'49'!$C$9:$C$567,$C6) -> 0 | I6: =SUMIFS('49'!K$9:K$567,'49'!$C$9:$C$567,$C6) -> 0 | J6: =SUMIFS('49'!L$9:L$567,'49'!$C$9:$C$567,$C6) -> 0 | K6: =SUMIFS('49'!M$9:M$567,'49'!$C$9:$C$567,$C6) -> 0 | L6: =SUMIFS('49'!N$9:N$567,'49'!$C$9:$C$567,$C6) -> 0 | ... P6: =SUMIFS('49'!R$9:R$567,'49'!$C$9:$C$567,$C6) -> 0 | Q6: =SUMIFS('49'!G$575:G$594,'49'!$C$575:$C$594,$C6) -> 0 | R6: =SUMIFS('49'!H$575:H$594,'49'!$C$575:$C$594,$C6) -> 0 | S6: =SUMIFS('49'!I$575:I$594,'49'!$C$575:$C$594,$C6) -> 0 | T6: =SUMIFS('49'!J$575:J$594,'49'!$C$575:$C$594,$C6) -> 0 | U6: =SUMIFS('49'!K$575:K$594,'49'!$C$575:$C$594,$C6) -> 0 | V6: =SUMIFS('49'!L$575:L$594,'49'!$C$575:$C$594,$C6) -> 0 | W6: =SUMIFS('49'!M$575:M$594,'49'!$C$575:$C$594,$C6) -> 0 | X6: =SUMIFS('49'!N$575:N$594,'49'!$C$575:$C$594,$C6) -> 0 | ... AB6: =SUMIFS('49'!R$575:R$594,'49'!$C$575:$C$594,$C6) -> 0 | AC6: =SUM(E6:AB6) -> 171860.63
B7: Sul | C7: CL | D7: Campo Limpo | E7: =SUMIFS('49'!G$9:G$567,'49'!$C$9:$C$567,$C7) -> 109398.43 | F7: =SUMIFS('49'!H$9:H$567,'49'!$C$9:$C$567,$C7) -> 18186.62 | G7: =SUMIFS('49'!I$9:I$567,'49'!$C$9:$C$567,$C7) -> 0 | H7: =SUMIFS('49'!J$9:J$567,'49'!$C$9:$C$567,$C7) -> 0 | I7: =SUMIFS('49'!K$9:K$567,'49'!$C$9:$C$567,$C7) -> 0 | J7: =SUMIFS('49'!L$9:L$567,'49'!$C$9:$C$567,$C7) -> 0 | K7: =SUMIFS('49'!M$9:M$567,'49'!$C$9:$C$567,$C7) -> 0 | L7: =SUMIFS('49'!N$9:N$567,'49'!$C$9:$C$567,$C7) -> 0 | ... P7: =SUMIFS('49'!R$9:R$567,'49'!$C$9:$C$567,$C7) -> 23439.86 | Q7: =SUMIFS('49'!G$575:G$594,'49'!$C$575:$C$594,$C7) -> 0 | R7: =SUMIFS('49'!H$575:H$594,'49'!$C$575:$C$594,$C7) -> 0 | S7: =SUMIFS('49'!I$575:I$594,'49'!$C$575:$C$594,$C7) -> 0 | T7: =SUMIFS('49'!J$575:J$594,'49'!$C$575:$C$594,$C7) -> 0 | U7: =SUMIFS('49'!K$575:K$594,'49'!$C$575:$C$594,$C7) -> 0 | V7: =SUMIFS('49'!L$575:L$594,'49'!$C$575:$C$594,$C7) -> 0 | W7: =SUMIFS('49'!M$575:M$594,'49'!$C$575:$C$594,$C7) -> 0 | X7: =SUMIFS('49'!N$575:N$594,'49'!$C$575:$C$594,$C7) -> 0 | ... AB7: =SUMIFS('49'!R$575:R$594,'49'!$C$575:$C$594,$C7) -> 0 | AC7: =SUM(E7:AB7) -> 194837.12
B8: Sul | C8: CS | D8: Capela do Socorro | E8: =SUMIFS('49'!G$9:G$567,'49'!$C$9:$C$567,$C8) -> 19005.16 | F8: =SUMIFS('49'!H$9:H$567,'49'!$C$9:$C$567,$C8) -> 0 | G8: =SUMIFS('49'!I$9:I$567,'49'!$C$9:$C$567,$C8) -> 0 | H8: =SUMIFS('49'!J$9:J$567,'49'!$C$9:$C$567,$C8) -> 0 | I8: =SUMIFS('49'!K$9:K$567,'49'!$C$9:$C$567,$C8) -> 0 | J8: =SUMIFS('49'!L$9:L$567,'49'!$C$9:$C$567,$C8) -> 0 | K8: =SUMIFS('49'!M$9:M$567,'49'!$C$9:$C$567,$C8) -> 0 | L8: =SUMIFS('49'!N$9:N$567,'49'!$C$9:$C$567,$C8) -> 0 | ... P8: =SUMIFS('49'!R$9:R$567,'49'!$C$9:$C$567,$C8) -> 0 | Q8: =SUMIFS('49'!G$575:G$594,'49'!$C$575:$C$594,$C8) -> 0 | R8: =SUMIFS('49'!H$575:H$594,'49'!$C$575:$C$594,$C8) -> 0 | S8: =SUMIFS('49'!I$575:I$594,'49'!$C$575:$C$594,$C8) -> 0 | T8: =SUMIFS('49'!J$575:J$594,'49'!$C$575:$C$594,$C8) -> 0 | U8: =SUMIFS('49'!K$575:K$594,'49'!$C$575:$C$594,$C8) -> 0 | V8: =SUMIFS('49'!L$575:L$594,'49'!$C$575:$C$594,$C8) -> 0 | W8: =SUMIFS('49'!M$575:M$594,'49'!$C$575:$C$594,$C8) -> 0 | X8: =SUMIFS('49'!N$575:N$594,'49'!$C$575:$C$594,$C8) -> 0 | ... AB8: =SUMIFS('49'!R$575:R$594,'49'!$C$575:$C$594,$C8) -> 0 | AC8: =SUM(E8:AB8) -> 19005.16
B9: Leste | C9: CT | D9: Cidade Tiradentes | E9: =SUMIFS('49'!G$9:G$567,'49'!$C$9:$C$567,$C9) -> 20651.36 | F9: =SUMIFS('49'!H$9:H$567,'49'!$C$9:$C$567,$C9) -> 10744.14 | G9: =SUMIFS('49'!I$9:I$567,'49'!$C$9:$C$567,$C9) -> 34903.02 | H9: =SUMIFS('49'!J$9:J$567,'49'!$C$9:$C$567,$C9) -> 24636.25 | I9: =SUMIFS('49'!K$9:K$567,'49'!$C$9:$C$567,$C9) -> 0 | J9: =SUMIFS('49'!L$9:L$567,'49'!$C$9:$C$567,$C9) -> 0 | K9: =SUMIFS('49'!M$9:M$567,'49'!$C$9:$C$567,$C9) -> 0 | L9: =SUMIFS('49'!N$9:N$567,'49'!$C$9:$C$567,$C9) -> 0 | ... P9: =SUMIFS('49'!R$9:R$567,'49'!$C$9:$C$567,$C9) -> 1929.67 | Q9: =SUMIFS('49'!G$575:G$594,'49'!$C$575:$C$594,$C9) -> 0 | R9: =SUMIFS('49'!H$575:H$594,'49'!$C$575:$C$594,$C9) -> 0 | S9: =SUMIFS('49'!I$575:I$594,'49'!$C$575:$C$594,$C9) -> 0 | T9: =SUMIFS('49'!J$575:J$594,'49'!$C$575:$C$594,$C9) -> 0 | U9: =SUMIFS('49'!K$575:K$594,'49'!$C$575:$C$594,$C9) -> 0 | V9: =SUMIFS('49'!L$575:L$594,'49'!$C$575:$C$594,$C9) -> 0 | W9: =SUMIFS('49'!M$575:M$594,'49'!$C$575:$C$594,$C9) -> 0 | X9: =SUMIFS('49'!N$575:N$594,'49'!$C$575:$C$594,$C9) -> 0 | ... AB9: =SUMIFS('49'!R$575:R$594,'49'!$C$575:$C$594,$C9) -> 0 | AC9: =SUM(E9:AB9) -> 92864.44
B10: Norte | C10: CV | D10: Casa Verde - Vila Nova Cachoeirinha | E10: =SUMIFS('49'!G$9:G$567,'49'!$C$9:$C$567,$C10) -> 51857.04 | F10: =SUMIFS('49'!H$9:H$567,'49'!$C$9:$C$567,$C10) -> 0 | G10: =SUMIFS('49'!I$9:I$567,'49'!$C$9:$C$567,$C10) -> 0 | H10: =SUMIFS('49'!J$9:J$567,'49'!$C$9:$C$567,$C10) -> 0 | I10: =SUMIFS('49'!K$9:K$567,'49'!$C$9:$C$567,$C10) -> 0 | J10: =SUMIFS('49'!L$9:L$567,'49'!$C$9:$C$567,$C10) -> 0 | K10: =SUMIFS('49'!M$9:M$567,'49'!$C$9:$C$567,$C10) -> 0 | L10: =SUMIFS('49'!N$9:N$567,'49'!$C$9:$C$567,$C10) -> 0 | ... P10: =SUMIFS('49'!R$9:R$567,'49'!$C$9:$C$567,$C10) -> 0 | Q10: =SUMIFS('49'!G$575:G$594,'49'!$C$575:$C$594,$C10) -> 17631 | R10: =SUMIFS('49'!H$575:H$594,'49'!$C$575:$C$594,$C10) -> 0 | S10: =SUMIFS('49'!I$575:I$594,'49'!$C$575:$C$594,$C10) -> 0 | T10: =SUMIFS('49'!J$575:J$594,'49'!$C$575:$C$594,$C10) -> 0 | U10: =SUMIFS('49'!K$575:K$594,'49'!$C$575:$C$594,$C10) -> 0 | V10: =SUMIFS('49'!L$575:L$594,'49'!$C$575:$C$594,$C10) -> 0 | W10: =SUMIFS('49'!M$575:M$594,'49'!$C$575:$C$594,$C10) -> 0 | X10: =SUMIFS('49'!N$575:N$594,'49'!$C$575:$C$594,$C10) -> 0 | ... AB10: =SUMIFS('49'!R$575:R$594,'49'!$C$575:$C$594,$C10) -> 0 | AC10: =SUM(E10:AB10) -> 76166.94
B11: Leste | C11: EM | D11: Ermelino Matarazzo | E11: =SUMIFS('49'!G$9:G$567,'49'!$C$9:$C$567,$C11) -> 9297.13 | F11: =SUMIFS('49'!H$9:H$567,'49'!$C$9:$C$567,$C11) -> 37205.67 | G11: =SUMIFS('49'!I$9:I$567,'49'!$C$9:$C$567,$C11) -> 21534.7 | H11: =SUMIFS('49'!J$9:J$567,'49'!$C$9:$C$567,$C11) -> 4988.8 | I11: =SUMIFS('49'!K$9:K$567,'49'!$C$9:$C$567,$C11) -> 6239.9 | J11: =SUMIFS('49'!L$9:L$567,'49'!$C$9:$C$567,$C11) -> 0 | K11: =SUMIFS('49'!M$9:M$567,'49'!$C$9:$C$567,$C11) -> 0 | L11: =SUMIFS('49'!N$9:N$567,'49'!$C$9:$C$567,$C11) -> 14998.5 | ... P11: =SUMIFS('49'!R$9:R$567,'49'!$C$9:$C$567,$C11) -> 0 | Q11: =SUMIFS('49'!G$575:G$594,'49'!$C$575:$C$594,$C11) -> 0 | R11: =SUMIFS('49'!H$575:H$594,'49'!$C$575:$C$594,$C11) -> 0 | S11: =SUMIFS('49'!I$575:I$594,'49'!$C$575:$C$594,$C11) -> 0 | T11: =SUMIFS('49'!J$575:J$594,'49'!$C$575:$C$594,$C11) -> 0 | U11: =SUMIFS('49'!K$575:K$594,'49'!$C$575:$C$594,$C11) -> 0 | V11: =SUMIFS('49'!L$575:L$594,'49'!$C$575:$C$594,$C11) -> 0 | W11: =SUMIFS('49'!M$575:M$594,'49'!$C$575:$C$594,$C11) -> 0 | X11: =SUMIFS('49'!N$575:N$594,'49'!$C$575:$C$594,$C11) -> 0 | ... AB11: =SUMIFS('49'!R$575:R$594,'49'!$C$575:$C$594,$C11) -> 0 | AC11: =SUM(E11:AB11) -> 123488.69
B12: Norte | C12: FB | D12: Freguesia do Ó - Vila Brasilândia | E12: =SUMIFS('49'!G$9:G$567,'49'!$C$9:$C$567,$C12) -> 39283.5 | F12: =SUMIFS('49'!H$9:H$567,'49'!$C$9:$C$567,$C12) -> 27363.08 | G12: =SUMIFS('49'!I$9:I$567,'49'!$C$9:$C$567,$C12) -> 0 | H12: =SUMIFS('49'!J$9:J$567,'49'!$C$9:$C$567,$C12) -> 0 | I12: =SUMIFS('49'!K$9:K$567,'49'!$C$9:$C$567,$C12) -> 0 | J12: =SUMIFS('49'!L$9:L$567,'49'!$C$9:$C$567,$C12) -> 0 | K12: =SUMIFS('49'!M$9:M$567,'49'!$C$9:$C$567,$C12) -> 1720 | L12: =SUMIFS('49'!N$9:N$567,'49'!$C$9:$C$567,$C12) -> 0 | ... P12: =SUMIFS('49'!R$9:R$567,'49'!$C$9:$C$567,$C12) -> 0 | Q12: =SUMIFS('49'!G$575:G$594,'49'!$C$575:$C$594,$C12) -> 0 | R12: =SUMIFS('49'!H$575:H$594,'49'!$C$575:$C$594,$C12) -> 0 | S12: =SUMIFS('49'!I$575:I$594,'49'!$C$575:$C$594,$C12) -> 0 | T12: =SUMIFS('49'!J$575:J$594,'49'!$C$575:$C$594,$C12) -> 0 | U12: =SUMIFS('49'!K$575:K$594,'49'!$C$575:$C$594,$C12) -> 0 | V12: =SUMIFS('49'!L$575:L$594,'49'!$C$575:$C$594,$C12) -> 0 | W12: =SUMIFS('49'!M$575:M$594,'49'!$C$575:$C$594,$C12) -> 0 | X12: =SUMIFS('49'!N$575:N$594,'49'!$C$575:$C$594,$C12) -> 0 | ... AB12: =SUMIFS('49'!R$575:R$594,'49'!$C$575:$C$594,$C12) -> 0 | AC12: =SUM(E12:AB12) -> 89401.78
B13: Leste | C13: G | D13: Guaianases | E13: =SUMIFS('49'!G$9:G$567,'49'!$C$9:$C$567,$C13) -> 64035.98 | F13: =SUMIFS('49'!H$9:H$567,'49'!$C$9:$C$567,$C13) -> 11442.44 | G13: =SUMIFS('49'!I$9:I$567,'49'!$C$9:$C$567,$C13) -> 9128.76 | H13: =SUMIFS('49'!J$9:J$567,'49'!$C$9:$C$567,$C13) -> 0 | I13: =SUMIFS('49'!K$9:K$567,'49'!$C$9:$C$567,$C13) -> 0 | J13: =SUMIFS('49'!L$9:L$567,'49'!$C$9:$C$567,$C13) -> 0 | K13: =SUMIFS('49'!M$9:M$567,'49'!$C$9:$C$567,$C13) -> 11437.51 | L13: =SUMIFS('49'!N$9:N$567,'49'!$C$9:$C$567,$C13) -> 0 | ... P13: =SUMIFS('49'!R$9:R$567,'49'!$C$9:$C$567,$C13) -> 0 | Q13: =SUMIFS('49'!G$575:G$594,'49'!$C$575:$C$594,$C13) -> 0 | R13: =SUMIFS('49'!H$575:H$594,'49'!$C$575:$C$594,$C13) -> 0 | S13: =SUMIFS('49'!I$575:I$594,'49'!$C$575:$C$594,$C13) -> 0 | T13: =SUMIFS('49'!J$575:J$594,'49'!$C$575:$C$594,$C13) -> 0 | U13: =SUMIFS('49'!K$575:K$594,'49'!$C$575:$C$594,$C13) -> 0 | V13: =SUMIFS('49'!L$575:L$594,'49'!$C$575:$C$594,$C13) -> 0 | W13: =SUMIFS('49'!M$575:M$594,'49'!$C$575:$C$594,$C13) -> 0 | X13: =SUMIFS('49'!N$575:N$594,'49'!$C$575:$C$594,$C13) -> 0 | ... AB13: =SUMIFS('49'!R$575:R$594,'49'!$C$575:$C$594,$C13) -> 0 | AC13: =SUM(E13:AB13) -> 96044.69
B14: Sul | C14: IP | D14: Ipiranga | E14: =SUMIFS('49'!G$9:G$567,'49'!$C$9:$C$567,$C14) -> 0 | F14: =SUMIFS('49'!H$9:H$567,'49'!$C$9:$C$567,$C14) -> 18698.94 | G14: =SUMIFS('49'!I$9:I$567,'49'!$C$9:$C$567,$C14) -> 15173.64 | H14: =SUMIFS('49'!J$9:J$567,'49'!$C$9:$C$567,$C14) -> 53562.21 | I14: =SUMIFS('49'!K$9:K$567,'49'!$C$9:$C$567,$C14) -> 0 | J14: =SUMIFS('49'!L$9:L$567,'49'!$C$9:$C$567,$C14) -> 0 | K14: =SUMIFS('49'!M$9:M$567,'49'!$C$9:$C$567,$C14) -> 0 | L14: =SUMIFS('49'!N$9:N$567,'49'!$C$9:$C$567,$C14) -> 3580.65 | ... P14: =SUMIFS('49'!R$9:R$567,'49'!$C$9:$C$567,$C14) -> 879 | Q14: =SUMIFS('49'!G$575:G$594,'49'!$C$575:$C$594,$C14) -> 0 | R14: =SUMIFS('49'!H$575:H$594,'49'!$C$575:$C$594,$C14) -> 0 | S14: =SUMIFS('49'!I$575:I$594,'49'!$C$575:$C$594,$C14) -> 0 | T14: =SUMIFS('49'!J$575:J$594,'49'!$C$575:$C$594,$C14) -> 0 | U14: =SUMIFS('49'!K$575:K$594,'49'!$C$575:$C$594,$C14) -> 0 | V14: =SUMIFS('49'!L$575:L$594,'49'!$C$575:$C$594,$C14) -> 0 | W14: =SUMIFS('49'!M$575:M$594,'49'!$C$575:$C$594,$C14) -> 0 | X14: =SUMIFS('49'!N$575:N$594,'49'!$C$575:$C$594,$C14) -> 0 | ... AB14: =SUMIFS('49'!R$575:R$594,'49'!$C$575:$C$594,$C14) -> 0 | AC14: =SUM(E14:AB14) -> 96574.64
B15: Leste | C15: IQ | D15: Itaquera | E15: =SUMIFS('49'!G$9:G$567,'49'!$C$9:$C$567,$C15) -> 23170.87 | F15: =SUMIFS('49'!H$9:H$567,'49'!$C$9:$C$567,$C15) -> 0 | G15: =SUMIFS('49'!I$9:I$567,'49'!$C$9:$C$567,$C15) -> 17185.72 | H15: =SUMIFS('49'!J$9:J$567,'49'!$C$9:$C$567,$C15) -> 40467.29 | I15: =SUMIFS('49'!K$9:K$567,'49'!$C$9:$C$567,$C15) -> 28705.09 | J15: =SUMIFS('49'!L$9:L$567,'49'!$C$9:$C$567,$C15) -> 9814.03 | K15: =SUMIFS('49'!M$9:M$567,'49'!$C$9:$C$567,$C15) -> 25827.62 | L15: =SUMIFS('49'!N$9:N$567,'49'!$C$9:$C$567,$C15) -> 0 | ... P15: =SUMIFS('49'!R$9:R$567,'49'!$C$9:$C$567,$C15) -> 5377.15 | Q15: =SUMIFS('49'!G$575:G$594,'49'!$C$575:$C$594,$C15) -> 0 | R15: =SUMIFS('49'!H$575:H$594,'49'!$C$575:$C$594,$C15) -> 0 | S15: =SUMIFS('49'!I$575:I$594,'49'!$C$575:$C$594,$C15) -> 0 | T15: =SUMIFS('49'!J$575:J$594,'49'!$C$575:$C$594,$C15) -> 0 | U15: =SUMIFS('49'!K$575:K$594,'49'!$C$575:$C$594,$C15) -> 0 | V15: =SUMIFS('49'!L$575:L$594,'49'!$C$575:$C$594,$C15) -> 0 | W15: =SUMIFS('49'!M$575:M$594,'49'!$C$575:$C$594,$C15) -> 0 | X15: =SUMIFS('49'!N$575:N$594,'49'!$C$575:$C$594,$C15) -> 0 | ... AB15: =SUMIFS('49'!R$575:R$594,'49'!$C$575:$C$594,$C15) -> 0 | AC15: =SUM(E15:AB15) -> 150547.77
... B35: Leste | C35: VP | D35: Vila Prudente | E35: =SUMIFS('49'!G$9:G$567,'49'!$C$9:$C$567,$C35) -> 40711.72 | F35: =SUMIFS('49'!H$9:H$567,'49'!$C$9:$C$567,$C35) -> 49552.59 | G35: =SUMIFS('49'!I$9:I$567,'49'!$C$9:$C$567,$C35) -> 12177.41 | H35: =SUMIFS('49'!J$9:J$567,'49'!$C$9:$C$567,$C35) -> 36683.17 | I35: =SUMIFS('49'!K$9:K$567,'49'!$C$9:$C$567,$C35) -> 0 | J35: =SUMIFS('49'!L$9:L$567,'49'!$C$9:$C$567,$C35) -> 0 | K35: =SUMIFS('49'!M$9:M$567,'49'!$C$9:$C$567,$C35) -> 0 | L35: =SUMIFS('49'!N$9:N$567,'49'!$C$9:$C$567,$C35) -> 0 | ... P35: =SUMIFS('49'!R$9:R$567,'49'!$C$9:$C$567,$C35) -> 5664.43 | Q35: =SUMIFS('49'!G$575:G$594,'49'!$C$575:$C$594,$C35) -> 0 | R35: =SUMIFS('49'!H$575:H$594,'49'!$C$575:$C$594,$C35) -> 0 | S35: =SUMIFS('49'!I$575:I$594,'49'!$C$575:$C$594,$C35) -> 0 | T35: =SUMIFS('49'!J$575:J$594,'49'!$C$575:$C$594,$C35) -> 0 | U35: =SUMIFS('49'!K$575:K$594,'49'!$C$575:$C$594,$C35) -> 0 | V35: =SUMIFS('49'!L$575:L$594,'49'!$C$575:$C$594,$C35) -> 0 | W35: =SUMIFS('49'!M$575:M$594,'49'!$C$575:$C$594,$C35) -> 0 | X35: =SUMIFS('49'!N$575:N$594,'49'!$C$575:$C$594,$C35) -> 0 | ... AB35: =SUMIFS('49'!R$575:R$594,'49'!$C$575:$C$594,$C35) -> 0 | AC35: =SUM(E35:AB35) -> 144789.32
B36: Total Executado por Mês (m²) | E36: =SUM(E4:E35) -> 1206286.1 | F36: =SUM(F4:F35) -> 511053.41 | G36: =SUM(G4:G35) -> 457360.76 | H36: =SUM(H4:H35) -> 389185.75 | I36: =SUM(I4:I35) -> 124802.19 | J36: =SUM(J4:J35) -> 88548.39 | K36: =SUM(K4:K35) -> 118614.86 | L36: =SUM(L4:L35) -> 58912.25 | ... AC36: =SUM(AC4:AC35) -> 3475401.6
